<?xml version="1.0"?>
<robot name="myfirst">
  <link name="base_link">
    <visual>
      <geometry>
        <box size="0.15 0.45 0.6" />
      </geometry>
    </visual>
  </link>

  <link name="shoulder">
    <visual>
      <origin rpy="0 0 0" xyz="0 0 0.02"/>
      <geometry>
        <cylinder length="0.04" radius="0.04"/>
      </geometry>
    </visual>
  </link>

  <joint name="t1" type="revolute">
    <axis xyz="0 1 0" />
    <limit effort="1000.0" lower="0.0" upper="0.548" velocity="0.5" />
    <origin rpy="1.570796 0 0" xyz="0 -0.21 0.2" />
    <parent link="base_link"/>
    <child link="shoulder"/> 
  </joint>
</robot>
